Workbook
Name shpКнопкаСведения: 'Краткая сводка'!$M$33
Name доход: tblДоходыПодстановка[Доходы]
Name значения_отображаемых_статей_расходов_за_период: OFFSET(отображаемые_статьи_расходов,,период)
Name количество_отображаемых_статей_расходов: COUNTIF('Данные диаграммы'!$B$7:$B$21,">"& " ")
Name НазваниеБюджета: Настройка!$B$1
Name НачальнаяЯчейка: 'Данные диаграммы'!$B$6
Name НачальныйБаланс: Бюджет!$C$5
Name отображаемые_статьи_расходов: OFFSET(НачальнаяЯчейка,15-количество_отображаемых_статей_расходов+1,,количество_отображаемых_статей_расходов)
Name отображать_длительный_период: CHOOSE(период,"Январь","Февраль","Март","Апрель","Май","Июнь","Июль","Август","Сентябрь","Октябрь","Ноябрь","Декабрь","Год")
Name период: 'Данные диаграммы'!$C$4
Name Печать_заголовков: Бюджет!$1:$4
Name расходы_благотворительность: tblРасходыБлаготворительность[Благотворительность]
Name расходы_быт_нужды: tblРасходыБытНужды[Бытовые нужды]
Name расходы_выплаты: tblРасходыВыплаты[Выплаты]
Name расходы_дети: tblРасходыДети[Дети]
Name расходы_домашние_животные: tblРасходыДомЖивотные[Домашние животные]
Name расходы_жилье: tblРасходыЖилье[Жилье]
Name расходы_здоровье: tblРасходыЗдоровье[Здоровье]
Name расходы_образование: tblРасходыОбразование[Образование]
Name расходы_отдых: tblРасходыОтдых[Отдых]
Name расходы_подписки: tblРасходыПодписки[Подписки]
Name расходы_развлечения: tblРасходыPазвлечения[Развлечения]
Name расходы_разное: tblРасходыРазное[Разное]
Name расходы_сбережения: tblРасходыСбережения[Сбережения]
Name расходы_страховка: tblРасходыСтраховка[Страховка]
Name расходы_транспорт: tblРасходыТранспорт[Транспорт]
Name статьи_расходов: tblСтатьиРасходов[Расходы]

Sheet Краткая сводка
N1: ="ИНТЕРАКТИВНЫЙ БЮДЖЕТ "&НазваниеБюджета -> ИНТЕРАКТИВНЫЙ БЮДЖЕТ СЕМЬЯ ЕГОРОВЫХ, 2012 год
A3: ='Данные диаграммы'!C38 -> 4000
D5: Доходы
A7: ='Данные диаграммы'!C39 -> 5933
D9: Расходы
A11: ='Данные диаграммы'!D40&'Данные диаграммы'!C40& "р." -> -1933р.
D13: Движение средств

Sheet Бюджет
C1: Янв. | D1: Февр. | E1: Март | F1: Апр. | G1: Май | H1: Июнь | I1: Июль | J1: Авг. | K1: Сент. | L1: Сент. | M1: Нояб. | N1: Дек. | O1: Год | P1: Ср.
B5: Начальная сумма | C5: 1000
B6: Общие доходы | C6: =SUM(tblДоход[jan]) -> 4222 | D6: =SUM(tblДоход[feb]) -> 9033 | E6: =SUM(tblДоход[mar]) -> 4000 | F6: =SUM(tblДоход[apr]) -> 4045 | G6: =SUM(tblДоход[may]) -> 9000 | H6: =SUM(tblДоход[jun]) -> 1525 | I6: =SUM(tblДоход[jul]) -> 1500 | J6: =SUM(tblДоход[aug]) -> 6500 | K6: =SUM(tblДоход[sep]) -> 4000 | L6: =SUM(tblДоход[oct]) -> 4000 | M6: =SUM(tblДоход[nov]) -> 9000 | N6: =SUM(tblДоход[dec]) -> 4000 | O6: =SUM(tblДоход[year]) -> 60825 | P6: =O6/12 -> 5068.75
B7: Общие расходы | C7: =SUM(tblСтатьяРасходов_01[jan],tblСтатьяРасходов_02[jan],tblСтатьяРасходов_03[jan],tblСтатьяРасходов_04[jan],tblСтатьяРасходов_05[jan],tblСтатьяРасходов_06[jan],tblСтатьяРасходов_07[jan],tblСтатьяРасходов_08[jan],tblСтатьяРасходов_09[jan],tblСтатьяРасходов_10[jan],tblСтатьяРасходов_11[jan],tblСтатьяРасходов_12[jan],tblСтатьяРасходов_13[jan],tblСтатьяРасходов_14[jan],tblСтатьяРасходов_15[jan]) -> 7936 | D7: =SUM(tblСтатьяРасходов_01[feb],tblСтатьяРасходов_02[feb],tblСтатьяРасходов_03[feb],tblСтатьяРасходов_04[feb],tblСтатьяРасходов_05[feb],tblСтатьяРасходов_06[feb],tblСтатьяРасходов_07[feb],tblСтатьяРасходов_08[feb],tblСтатьяРасходов_09[feb],tblСтатьяРасходов_10[feb],tblСтатьяРасходов_11[feb],tblСтатьяРасходов_12[feb],tblСтатьяРасходов_13[feb],tblСтатьяРасходов_14[feb],tblСтатьяРасходов_15[feb]) -> 5243 | E7: =SUM(tblСтатьяРасходов_01[mar],tblСтатьяРасходов_02[mar],tblСтатьяРасходов_03[mar],tblСтатьяРасходов_04[mar],tblСтатьяРасходов_05[mar],tblСтатьяРасходов_06[mar],tblСтатьяРасходов_07[mar],tblСтатьяРасходов_08[mar],tblСтатьяРасходов_09[mar],tblСтатьяРасходов_10[mar],tblСтатьяРасходов_11[mar],tblСтатьяРасходов_12[mar],tblСтатьяРасходов_13[mar],tblСтатьяРасходов_14[mar],tblСтатьяРасходов_15[mar]) -> 5933 | F7: =SUM(tblСтатьяРасходов_01[apr],tblСтатьяРасходов_02[apr],tblСтатьяРасходов_03[apr],tblСтатьяРасходов_04[apr],tblСтатьяРасходов_05[apr],tblСтатьяРасходов_06[apr],tblСтатьяРасходов_07[apr],tblСтатьяРасходов_08[apr],tblСтатьяРасходов_09[apr],tblСтатьяРасходов_10[apr],tblСтатьяРасходов_11[apr],tblСтатьяРасходов_12[apr],tblСтатьяРасходов_13[apr],tblСтатьяРасходов_14[apr],tblСтатьяРасходов_15[apr]) -> 5858 | G7: =SUM(tblСтатьяРасходов_01[may],tblСтатьяРасходов_02[may],tblСтатьяРасходов_03[may],tblСтатьяРасходов_04[may],tblСтатьяРасходов_05[may],tblСтатьяРасходов_06[may],tblСтатьяРасходов_07[may],tblСтатьяРасходов_08[may],tblСтатьяРасходов_09[may],tblСтатьяРасходов_10[may],tblСтатьяРасходов_11[may],tblСтатьяРасходов_12[may],tblСтатьяРасходов_13[may],tblСтатьяРасходов_14[may],tblСтатьяРасходов_15[may]) -> 5468 | H7: =SUM(tblСтатьяРасходов_01[jun],tblСтатьяРасходов_02[jun],tblСтатьяРасходов_03[jun],tblСтатьяРасходов_04[jun],tblСтатьяРасходов_05[jun],tblСтатьяРасходов_06[jun],tblСтатьяРасходов_07[jun],tblСтатьяРасходов_08[jun],tblСтатьяРасходов_09[jun],tblСтатьяРасходов_10[jun],tblСтатьяРасходов_11[jun],tblСтатьяРасходов_12[jun],tblСтатьяРасходов_13[jun],tblСтатьяРасходов_14[jun],tblСтатьяРасходов_15[jun]) -> 5118 | I7: =SUM(tblСтатьяРасходов_01[jul],tblСтатьяРасходов_02[jul],tblСтатьяРасходов_03[jul],tblСтатьяРасходов_04[jul],tblСтатьяРасходов_05[jul],tblСтатьяРасходов_06[jul],tblСтатьяРасходов_07[jul],tblСтатьяРасходов_08[jul],tblСтатьяРасходов_09[jul],tblСтатьяРасходов_10[jul],tblСтатьяРасходов_11[jul],tblСтатьяРасходов_12[jul],tblСтатьяРасходов_13[jul],tblСтатьяРасходов_14[jul],tblСтатьяРасходов_15[jul]) -> 5743 | J7: =SUM(tblСтатьяРасходов_01[aug],tblСтатьяРасходов_02[aug],tblСтатьяРасходов_03[aug],tblСтатьяРасходов_04[aug],tblСтатьяРасходов_05[aug],tblСтатьяРасходов_06[aug],tblСтатьяРасходов_07[aug],tblСтатьяРасходов_08[aug],tblСтатьяРасходов_09[aug],tblСтатьяРасходов_10[aug],tblСтатьяРасходов_11[aug],tblСтатьяРасходов_12[aug],tblСтатьяРасходов_13[aug],tblСтатьяРасходов_14[aug],tblСтатьяРасходов_15[aug]) -> 5353 | K7: =SUM(tblСтатьяРасходов_01[sep],tblСтатьяРасходов_02[sep],tblСтатьяРасходов_03[sep],tblСтатьяРасходов_04[sep],tblСтатьяРасходов_05[sep],tblСтатьяРасходов_06[sep],tblСтатьяРасходов_07[sep],tblСтатьяРасходов_08[sep],tblСтатьяРасходов_09[sep],tblСтатьяРасходов_10[sep],tblСтатьяРасходов_11[sep],tblСтатьяРасходов_12[sep],tblСтатьяРасходов_13[sep],tblСтатьяРасходов_14[sep],tblСтатьяРасходов_15[sep]) -> 5983 | L7: =SUM(tblСтатьяРасходов_01[oct],tblСтатьяРасходов_02[oct],tblСтатьяРасходов_03[oct],tblСтатьяРасходов_04[oct],tblСтатьяРасходов_05[oct],tblСтатьяРасходов_06[oct],tblСтатьяРасходов_07[oct],tblСтатьяРасходов_08[oct],tblСтатьяРасходов_09[oct],tblСтатьяРасходов_10[oct],tblСтатьяРасходов_11[oct],tblСтатьяРасходов_12[oct],tblСтатьяРасходов_13[oct],tblСтатьяРасходов_14[oct],tblСтатьяРасходов_15[oct]) -> 5943 | M7: =SUM(tblСтатьяРасходов_01[nov],tblСтатьяРасходов_02[nov],tblСтатьяРасходов_03[nov],tblСтатьяРасходов_04[nov],tblСтатьяРасходов_05[nov],tblСтатьяРасходов_06[nov],tblСтатьяРасходов_07[nov],tblСтатьяРасходов_08[nov],tblСтатьяРасходов_09[nov],tblСтатьяРасходов_10[nov],tblСтатьяРасходов_11[nov],tblСтатьяРасходов_12[nov],tblСтатьяРасходов_13[nov],tblСтатьяРасходов_14[nov],tblСтатьяРасходов_15[nov]) -> 5058 | N7: =SUM(tblСтатьяРасходов_01[dec],tblСтатьяРасходов_02[dec],tblСтатьяРасходов_03[dec],tblСтатьяРасходов_04[dec],tblСтатьяРасходов_05[dec],tblСтатьяРасходов_06[dec],tblСтатьяРасходов_07[dec],tblСтатьяРасходов_08[dec],tblСтатьяРасходов_09[dec],tblСтатьяРасходов_10[dec],tblСтатьяРасходов_11[dec],tblСтатьяРасходов_12[dec],tblСтатьяРасходов_13[dec],tblСтатьяРасходов_14[dec],tblСтатьяРасходов_15[dec]) -> 4958 | O7: =SUM(tblСтатьяРасходов_01[year],tblСтатьяРасходов_02[year],tblСтатьяРасходов_03[year],tblСтатьяРасходов_04[year],tblСтатьяРасходов_05[year],tblСтатьяРасходов_06[year],tblСтатьяРасходов_07[year],tblСтатьяРасходов_08[year],tblСтатьяРасходов_09[year],tblСтатьяРасходов_10[year],tblСтатьяРасходов_11[year],tblСтатьяРасходов_12[year],tblСтатьяРасходов_13[year],tblСтатьяРасходов_14[year],tblСтатьяРасходов_15[year]) -> 68594 | P7: =O7/12 -> 5716.1667
B8: Чистый доход | C8: =C6-C7 -> -3714 | D8: =D6-D7 -> 3790 | E8: =E6-E7 -> -1933 | F8: =F6-F7 -> -1813 | G8: =G6-G7 -> 3532 | H8: =H6-H7 -> -3593 | I8: =I6-I7 -> -4243 | J8: =J6-J7 -> 1147 | ... O8: =O6-O7 -> -7769 | P8: =O8/12 -> -647.41667
B9: ОБЩЕЕ ДВИЖЕНИЕ СРЕДСТВ | C9: =C5+C6-C7 -> -2714 | D9: =C9+D6-D7 -> 1076 | E9: =D9+E6-E7 -> -857 | F9: =E9+F6-F7 -> -2670 | G9: =F9+G6-G7 -> 862 | H9: =G9+H6-H7 -> -2731 | I9: =H9+I6-I7 -> -6974 | J9: =I9+J6-J7 -> -5827 | K9: =J9+K6-K7 -> -7810 | ... N9: =M9+N6-N7 -> -6769
B12: Доходы
B13: Заработная плата и чаевые | C13: 4000 | D13: 4000 | E13: 4000 | F13: 4000 | G13: 4000 | H13: 1000 | I13: 1000 | J13: 1000 | K13: 4000 | L13: 4000 | M13: 4000 | N13: 4000 | O13: =SUM(tblДоход[[#This Row],[jan]:[dec]]) -> 39000 | P13: =tblДоход[[#This Row],[year]]/12 -> 3250
B14: Доход от процентов | C14: 222 | D14: 33 | F14: 45 | H14: 25 | O14: =SUM(tblДоход[[#This Row],[jan]:[dec]]) -> 325 | P14: =tblДоход[[#This Row],[year]]/12 -> 27.083333
B15: Дивиденды | D15: 5000 | G15: 5000 | J15: 5000 | M15: 5000 | O15: =SUM(tblДоход[[#This Row],[jan]:[dec]]) -> 20000 | P15: =tblДоход[[#This Row],[year]]/12 -> 1666.6667
B16: Возмещения и компенсации | H16: 500 | I16: 500 | J16: 500 | O16: =SUM(tblДоход[[#This Row],[jan]:[dec]]) -> 1500 | P16: =tblДоход[[#This Row],[year]]/12 -> 125
B17: Прочее | O17: =SUM(tblДоход[[#This Row],[jan]:[dec]]) -> 0 | P17: =tblДоход[[#This Row],[year]]/12 -> 0
B18: ОБЩИЕ ДОХОДЫ | C18: =SUM(tblДоход[jan]) -> 4222 | D18: =SUM(tblДоход[feb]) -> 9033 | E18: =SUM(tblДоход[mar]) -> 4000 | F18: =SUM(tblДоход[apr]) -> 4045 | G18: =SUM(tblДоход[may]) -> 9000 | H18: =SUM(tblДоход[jun]) -> 1525 | I18: =SUM(tblДоход[jul]) -> 1500 | J18: =SUM(tblДоход[aug]) -> 6500 | K18: =SUM(tblДоход[sep]) -> 4000 | L18: =SUM(tblДоход[oct]) -> 4000 | M18: =SUM(tblДоход[nov]) -> 9000 | N18: =SUM(tblДоход[dec]) -> 4000 | O18: =SUM(tblДоход[year]) -> 60825 | P18: =tblДоход[[#Totals],[year]]/12 -> 5068.75
B21: Жилье
B22: Ипотека или аренда | C22: 850 | D22: 850 | E22: 850 | F22: 850 | G22: 850 | H22: 850 | I22: 850 | J22: 850 | K22: 850 | L22: 850 | M22: 900 | N22: 900 | O22: =SUM(tblСтатьяРасходов_01[[#This Row],[jan]:[dec]]) -> 10300 | P22: =tblСтатьяРасходов_01[[#This Row],[year]]/12 -> 858.33333
B23: Электроэнергия | C23: 200 | D23: 200 | E23: 175 | F23: 150 | G23: 150 | H23: 175 | I23: 225 | J23: 275 | K23: 200 | L23: 150 | M23: 150 | N23: 150 | O23: =SUM(tblСтатьяРасходов_01[[#This Row],[jan]:[dec]]) -> 2200 | P23: =tblСтатьяРасходов_01[[#This Row],[year]]/12 -> 183.33333
B24: Телефон | C24: 50 | D24: 50 | E24: 100 | F24: 100 | G24: 50 | H24: 50 | I24: 100 | J24: 100 | K24: 50 | L24: 50 | M24: 50 | N24: 50 | O24: =SUM(tblСтатьяРасходов_01[[#This Row],[jan]:[dec]]) -> 800 | P24: =tblСтатьяРасходов_01[[#This Row],[year]]/12 -> 66.666667
B25: Кабельное или спутниковое ТВ | C25: 69 | D25: 69 | E25: 69 | F25: 69 | G25: 69 | H25: 69 | I25: 69 | J25: 69 | K25: 69 | L25: 69 | M25: 69 | N25: 69 | O25: =SUM(tblСтатьяРасходов_01[[#This Row],[jan]:[dec]]) -> 828 | P25: =tblСтатьяРасходов_01[[#This Row],[year]]/12 -> 69
B26: Интернет | C26: 39 | D26: 39 | E26: 39 | F26: 39 | G26: 39 | H26: 39 | I26: 39 | J26: 39 | K26: 39 | L26: 39 | M26: 39 | N26: 39 | O26: =SUM(tblСтатьяРасходов_01[[#This Row],[jan]:[dec]]) -> 468 | P26: =tblСтатьяРасходов_01[[#This Row],[year]]/12 -> 39
B27: =UPPER("ВСЕГО: " & B21) -> ВСЕГО: ЖИЛЬЕ | C27: =SUM(tblСтатьяРасходов_01[jan]) -> 1208 | D27: =SUM(tblСтатьяРасходов_01[feb]) -> 1208 | E27: =SUM(tblСтатьяРасходов_01[mar]) -> 1233 | F27: =SUM(tblСтатьяРасходов_01[apr]) -> 1208 | G27: =SUM(tblСтатьяРасходов_01[may]) -> 1158 | H27: =SUM(tblСтатьяРасходов_01[jun]) -> 1183 | I27: =SUM(tblСтатьяРасходов_01[jul]) -> 1283 | J27: =SUM(tblСтатьяРасходов_01[aug]) -> 1333 | K27: =SUM(tblСтатьяРасходов_01[sep]) -> 1208 | L27: =SUM(tblСтатьяРасходов_01[oct]) -> 1158 | M27: =SUM(tblСтатьяРасходов_01[nov]) -> 1208 | N27: =SUM(tblСтатьяРасходов_01[dec]) -> 1208 | O27: =SUM(tblСтатьяРасходов_01[year]) -> 14596 | P27: =tblСтатьяРасходов_01[[#Totals],[year]]/12 -> 1216.3333
B30: Бытовые нужды
B31: Продукты | C31: 345 | D31: 250 | E31: 200 | F31: 400 | G31: 350 | H31: 250 | I31: 400 | J31: 350 | K31: 250 | L31: 400 | M31: 350 | N31: 250 | O31: =SUM(tblСтатьяРасходов_02[[#This Row],[jan]:[dec]]) -> 3795 | P31: =tblСтатьяРасходов_02[[#This Row],[year]]/12 -> 316.25
B32: Одежда | C32: 300 | F32: 300 | I32: 300 | L32: 300 | O32: =SUM(tblСтатьяРасходов_02[[#This Row],[jan]:[dec]]) -> 1200 | P32: =tblСтатьяРасходов_02[[#This Row],[year]]/12 -> 100
B33: Питание вне дома | C33: 125 | D33: 125 | E33: 300 | F33: 125 | G33: 125 | H33: 200 | I33: 125 | J33: 125 | K33: 125 | L33: 125 | M33: 125 | N33: 125 | O33: =SUM(tblСтатьяРасходов_02[[#This Row],[jan]:[dec]]) -> 1750 | P33: =tblСтатьяРасходов_02[[#This Row],[year]]/12 -> 145.83333
B34: Салон красоты или парикмахерская | C34: 25 | E34: 50 | G34: 25 | I34: 50 | K34: 25 | M34: 100 | O34: =SUM(tblСтатьяРасходов_02[[#This Row],[jan]:[dec]]) -> 275 | P34: =tblСтатьяРасходов_02[[#This Row],[year]]/12 -> 22.916667
B35: Прочее | O35: =SUM(tblСтатьяРасходов_02[[#This Row],[jan]:[dec]]) -> 0 | P35: =tblСтатьяРасходов_02[[#This Row],[year]]/12 -> 0
B36: =UPPER("ВСЕГО: " & B30) -> ВСЕГО: БЫТОВЫЕ НУЖДЫ | C36: =SUM(tblСтатьяРасходов_02[jan]) -> 795 | D36: =SUM(tblСтатьяРасходов_02[feb]) -> 375 | E36: =SUM(tblСтатьяРасходов_02[mar]) -> 550 | F36: =SUM(tblСтатьяРасходов_02[apr]) -> 825 | G36: =SUM(tblСтатьяРасходов_02[may]) -> 500 | H36: =SUM(tblСтатьяРасходов_02[jun]) -> 450 | I36: =SUM(tblСтатьяРасходов_02[jul]) -> 875 | J36: =SUM(tblСтатьяРасходов_02[aug]) -> 475 | K36: =SUM(tblСтатьяРасходов_02[sep]) -> 400 | L36: =SUM(tblСтатьяРасходов_02[oct]) -> 825 | M36: =SUM(tblСтатьяРасходов_02[nov]) -> 575 | N36: =SUM(tblСтатьяРасходов_02[dec]) -> 375 | O36: =SUM(tblСтатьяРасходов_02[year]) -> 7020 | P36: =tblСтатьяРасходов_02[[#Totals],[year]]/12 -> 585
B39: Дети
B40: Школьные принадлежности | C40: 123 | E40: 100 | J40: 345 | O40: =SUM(tblСтатьяРасходов_03[[#This Row],[jan]:[dec]]) -> 568 | P40: =tblСтатьяРасходов_03[[#This Row],[year]]/12 -> 47.333333
B41: Одежда | D41: 100 | G41: 100 | K41: 100 | N41: 100 | O41: =SUM(tblСтатьяРасходов_03[[#This Row],[jan]:[dec]]) -> 400 | P41: =tblСтатьяРасходов_03[[#This Row],[year]]/12 -> 33.333333
B42: Обед в школе | C42: 50 | D42: 50 | E42: 50 | F42: 50 | G42: 50 | H42: 50 | K42: 50 | L42: 50 | M42: 50 | N42: 50 | O42: =SUM(tblСтатьяРасходов_03[[#This Row],[jan]:[dec]]) -> 500 | P42: =tblСтатьяРасходов_03[[#This Row],[year]]/12 -> 41.666667
B43: Медицинские услуги | C43: 200 | D43: 200 | E43: 200 | F43: 200 | G43: 200 | H43: 200 | I43: 200 | J43: 200 | K43: 200 | L43: 200 | M43: 200 | N43: 200 | O43: =SUM(tblСтатьяРасходов_03[[#This Row],[jan]:[dec]]) -> 2400 | P43: =tblСтатьяРасходов_03[[#This Row],[year]]/12 -> 200
B44: Прочее | C44: 2000 | D44: 150 | H44: 200 | L44: 100 | O44: =SUM(tblСтатьяРасходов_03[[#This Row],[jan]:[dec]]) -> 2450 | P44: =tblСтатьяРасходов_03[[#This Row],[year]]/12 -> 204.16667
B45: =UPPER("ВСЕГО: " & B39) -> ВСЕГО: ДЕТИ | C45: =SUM(tblСтатьяРасходов_03[jan]) -> 2373 | D45: =SUM(tblСтатьяРасходов_03[feb]) -> 500 | E45: =SUM(tblСтатьяРасходов_03[mar]) -> 350 | F45: =SUM(tblСтатьяРасходов_03[apr]) -> 250 | G45: =SUM(tblСтатьяРасходов_03[may]) -> 350 | H45: =SUM(tblСтатьяРасходов_03[jun]) -> 450 | I45: =SUM(tblСтатьяРасходов_03[jul]) -> 200 | J45: =SUM(tblСтатьяРасходов_03[aug]) -> 545 | K45: =SUM(tblСтатьяРасходов_03[sep]) -> 350 | L45: =SUM(tblСтатьяРасходов_03[oct]) -> 350 | M45: =SUM(tblСтатьяРасходов_03[nov]) -> 250 | N45: =SUM(tblСтатьяРасходов_03[dec]) -> 350 | O45: =SUM(tblСтатьяРасходов_03[year]) -> 6318 | P45: =tblСтатьяРасходов_03[[#Totals],[year]]/12 -> 526.5
B48: Транспорт
B49: Расходы на автомобиль | C49: 600 | D49: 600 | E49: 600 | F49: 600 | G49: 600 | H49: 600 | I49: 600 | J49: 600 | K49: 600 | L49: 600 | M49: 600 | N49: 600 | O49: =SUM(tblСтатьяРасходов_04[[#This Row],[jan]:[dec]]) -> 7200 | P49: =tblСтатьяРасходов_04[[#This Row],[year]]/12 -> 600
B50: Топливо | C50: 325 | D50: 325 | E50: 325 | F50: 325 | G50: 325 | H50: 500 | I50: 500 | J50: 500 | K50: 325 | L50: 325 | M50: 325 | N50: 325 | O50: =SUM(tblСтатьяРасходов_04[[#This Row],[jan]:[dec]]) -> 4425 | P50: =tblСтатьяРасходов_04[[#This Row],[year]]/12 -> 368.75
B51: Ремонт | D51: 100 | F51: 100 | H51: 100 | J51: 100 | L51: 100 | O51: =SUM(tblСтатьяРасходов_04[[#This Row],[jan]:[dec]]) -> 500 | P51: =tblСтатьяРасходов_04[[#This Row],[year]]/12 -> 41.666667
B52: Регистрация и удостоверение | C52: 185 | K52: 225 | O52: =SUM(tblСтатьяРасходов_04[[#This Row],[jan]:[dec]]) -> 410 | P52: =tblСтатьяРасходов_04[[#This Row],[year]]/12 -> 34.166667
B53: Прочее | G53: 400 | O53: =SUM(tblСтатьяРасходов_04[[#This Row],[jan]:[dec]]) -> 400 | P53: =tblСтатьяРасходов_04[[#This Row],[year]]/12 -> 33.333333
...

Sheet Настройка
B1: СЕМЬЯ ЕГОРОВЫХ, 2012 год
B2: Доходы | D2: Расходы
B3: Заработная плата и чаевые
B4: Доход от процентов | D4: Жилье | F4: Жилье | H4: Бытовые нужды | J4: Дети
B5: Дивиденды | D5: Бытовые нужды | F5: Ипотека или аренда | H5: Продукты | J5: Медицинские услуги
B6: Полученные подарки | D6: Дети | F6: Электроэнергия | H6: Средства личной гигиены | J6: Одежда
B7: Возмещения и компенсации | D7: Транспорт | F7: Отопление | H7: Одежда | J7: Обучение в школе
B8: Перевод из сбережений | D8: Здоровье | F8: Вода, канализация и вывоз мусора | H8: Услуги по уборке | J8: Обед в школе
B9: Прочее | D9: Страховка | F9: Телефон | H9: Питание вне дома | J9: Школьные принадлежности
D10: Образование | F10: Кабельное или спутниковое ТВ | H10: Химчистка | J10: Няня
D11: Благотворительность | F11: Интернет | H11: Салон красоты или парикмахерская | J11: Игрушки и игры
D12: Сбережения | F12: Мебель и бытовая техника | H12: Прочее | J12: Прочее
D13: Выплаты | F13: Газон или сад
D14: Развлечения | F14: Товары для дома
D15: Домашние животные | F15: Содержание жилья
D16: Подписки | F16: Ремонт дома
D17: Отдых | F17: Прочее
D18: Разное
F20: Транспорт | H20: Здоровье | J20: Страховка
F21: Расходы на автомобиль | H21: Стоматолог и другие врачи | J21: Автомобиль
F22: Топливо | H22: Лекарства | J22: Здоровье
F23: Общественный транспорт | H23: Абонементы в спортзалы | J23: Жилье (собственное или арендуемое)
F24: Ремонт | H24: Экстренная медицинская помощь | J24: Жизнь
F25: Регистрация и удостоверение | H25: Прочее | J25: Прочее
F26: Прочее
F29: Образование | H29: Благотворительность | J29: Сбережения
F30: Обучение | H30: Покупка подарков | J30: Чрезвычайный фонд
F31: Книги | H31: Пожертвования на благотворительность | J31: Перевод в сбережения
F32: Музыкальная школа | H32: Пожертвования храмам | J32: Пенсионные фонды (государственные и частные)
F33: Прочее | H33: Прочее | J33: Инвестиции
J34: Высшее образование
J35: Прочее
F38: Выплаты | H38: Развлечения | J38: Домашние животные
F39: Студенческий заем | H39: Видео и DVD-диски | J39: Питание
F40: Прочие займы | H40: Музыка | J40: Медицинские услуги
F41: Кредитная карта 1 | H41: Игры | J41: Игрушки и сопутствующие товары
F42: Кредитная карта 2 | H42: Прокат | J42: Прочее
F43: Кредитная карта 3 | H43: Кино и театр
F44: Алименты и детские пособия | H44: Концерты и матчи
F45: Федеральные налоги | H45: Книги
...

Sheet Данные диаграммы
B1: *** Этот лист должен оставаться скрытым ***
B4: Период | C4: 3
C6: Янв. | D6: Февр. | E6: Март | F6: Апр. | G6: Май | H6: Июнь | I6: Июль | J6: Авг. | K6: Сент. | L6: Окт. | M6: Нояб. | N6: Дек. | O6: Год | P6: Ср.
B7: =LOWER(Бюджет!B127) | C7: =SUM(tblСтатьяРасходов_15[jan]) -> 0 | D7: =SUM(tblСтатьяРасходов_15[feb]) -> 0 | E7: =SUM(tblСтатьяРасходов_15[mar]) -> 0 | F7: =SUM(tblСтатьяРасходов_15[apr]) -> 0 | G7: =SUM(tblСтатьяРасходов_15[may]) -> 0 | H7: =SUM(tblСтатьяРасходов_15[jun]) -> 0 | I7: =SUM(tblСтатьяРасходов_15[jul]) -> 0 | J7: =SUM(tblСтатьяРасходов_15[aug]) -> 0 | K7: =SUM(tblСтатьяРасходов_15[sep]) -> 0 | L7: =SUM(tblСтатьяРасходов_15[oct]) -> 0 | M7: =SUM(tblСтатьяРасходов_15[nov]) -> 0 | N7: =SUM(tblСтатьяРасходов_15[dec]) -> 0 | O7: =SUM(tblСтатьяРасходов_15[year]) -> 0 | P7: =SUM(tblСтатьяРасходов_15[avg]) -> 0
B8: =LOWER(Бюджет!B120) | C8: =SUM(tblСтатьяРасходов_14[jan]) -> 0 | D8: =SUM(tblСтатьяРасходов_14[feb]) -> 0 | E8: =SUM(tblСтатьяРасходов_14[mar]) -> 0 | F8: =SUM(tblСтатьяРасходов_14[apr]) -> 0 | G8: =SUM(tblСтатьяРасходов_14[may]) -> 0 | H8: =SUM(tblСтатьяРасходов_14[jun]) -> 0 | I8: =SUM(tblСтатьяРасходов_14[jul]) -> 0 | J8: =SUM(tblСтатьяРасходов_14[aug]) -> 0 | K8: =SUM(tblСтатьяРасходов_14[sep]) -> 0 | L8: =SUM(tblСтатьяРасходов_14[oct]) -> 0 | M8: =SUM(tblСтатьяРасходов_14[nov]) -> 0 | N8: =SUM(tblСтатьяРасходов_14[dec]) -> 0 | O8: =SUM(tblСтатьяРасходов_14[year]) -> 0 | P8: =SUM(tblСтатьяРасходов_14[avg]) -> 0
B9: =LOWER(Бюджет!B113) | C9: =SUM(tblСтатьяРасходов_13[jan]) -> 0 | D9: =SUM(tblСтатьяРасходов_13[feb]) -> 0 | E9: =SUM(tblСтатьяРасходов_13[mar]) -> 0 | F9: =SUM(tblСтатьяРасходов_13[apr]) -> 0 | G9: =SUM(tblСтатьяРасходов_13[may]) -> 0 | H9: =SUM(tblСтатьяРасходов_13[jun]) -> 0 | I9: =SUM(tblСтатьяРасходов_13[jul]) -> 0 | J9: =SUM(tblСтатьяРасходов_13[aug]) -> 0 | K9: =SUM(tblСтатьяРасходов_13[sep]) -> 0 | L9: =SUM(tblСтатьяРасходов_13[oct]) -> 0 | M9: =SUM(tblСтатьяРасходов_13[nov]) -> 0 | N9: =SUM(tblСтатьяРасходов_13[dec]) -> 0 | O9: =SUM(tblСтатьяРасходов_13[year]) -> 0 | P9: =SUM(tblСтатьяРасходов_13[avg]) -> 0
B10: =LOWER(Бюджет!B106) | C10: =SUM(tblСтатьяРасходов_12[jan]) -> 0 | D10: =SUM(tblСтатьяРасходов_12[feb]) -> 0 | E10: =SUM(tblСтатьяРасходов_12[mar]) -> 0 | F10: =SUM(tblСтатьяРасходов_12[apr]) -> 0 | G10: =SUM(tblСтатьяРасходов_12[may]) -> 0 | H10: =SUM(tblСтатьяРасходов_12[jun]) -> 0 | I10: =SUM(tblСтатьяРасходов_12[jul]) -> 0 | J10: =SUM(tblСтатьяРасходов_12[aug]) -> 0 | K10: =SUM(tblСтатьяРасходов_12[sep]) -> 0 | L10: =SUM(tblСтатьяРасходов_12[oct]) -> 0 | M10: =SUM(tblСтатьяРасходов_12[nov]) -> 0 | N10: =SUM(tblСтатьяРасходов_12[dec]) -> 0 | O10: =SUM(tblСтатьяРасходов_12[year]) -> 0 | P10: =SUM(tblСтатьяРасходов_12[avg]) -> 0
B11: =LOWER(Бюджет!B99) | C11: =SUM(tblСтатьяРасходов_11[jan]) -> 0 | D11: =SUM(tblСтатьяРасходов_11[feb]) -> 0 | E11: =SUM(tblСтатьяРасходов_11[mar]) -> 0 | F11: =SUM(tblСтатьяРасходов_11[apr]) -> 0 | G11: =SUM(tblСтатьяРасходов_11[may]) -> 0 | H11: =SUM(tblСтатьяРасходов_11[jun]) -> 0 | I11: =SUM(tblСтатьяРасходов_11[jul]) -> 0 | J11: =SUM(tblСтатьяРасходов_11[aug]) -> 0 | K11: =SUM(tblСтатьяРасходов_11[sep]) -> 0 | L11: =SUM(tblСтатьяРасходов_11[oct]) -> 0 | M11: =SUM(tblСтатьяРасходов_11[nov]) -> 0 | N11: =SUM(tblСтатьяРасходов_11[dec]) -> 0 | O11: =SUM(tblСтатьяРасходов_11[year]) -> 0 | P11: =SUM(tblСтатьяРасходов_11[avg]) -> 0
B12: =LOWER(Бюджет!B92) -> выплаты | C12: =SUM(tblСтатьяРасходов_10[jan]) -> 650 | D12: =SUM(tblСтатьяРасходов_10[feb]) -> 200 | E12: =SUM(tblСтатьяРасходов_10[mar]) -> 200 | F12: =SUM(tblСтатьяРасходов_10[apr]) -> 650 | G12: =SUM(tblСтатьяРасходов_10[may]) -> 200 | H12: =SUM(tblСтатьяРасходов_10[jun]) -> 200 | I12: =SUM(tblСтатьяРасходов_10[jul]) -> 650 | J12: =SUM(tblСтатьяРасходов_10[aug]) -> 200 | K12: =SUM(tblСтатьяРасходов_10[sep]) -> 200 | L12: =SUM(tblСтатьяРасходов_10[oct]) -> 650 | M12: =SUM(tblСтатьяРасходов_10[nov]) -> 200 | N12: =SUM(tblСтатьяРасходов_10[dec]) -> 200 | O12: =SUM(tblСтатьяРасходов_10[year]) -> 4200 | P12: =SUM(tblСтатьяРасходов_10[avg]) -> 350
B13: =LOWER(Бюджет!B85) -> сбережения | C13: =SUM(tblСтатьяРасходов_09[jan]) -> 800 | D13: =SUM(tblСтатьяРасходов_09[feb]) -> 800 | E13: =SUM(tblСтатьяРасходов_09[mar]) -> 800 | F13: =SUM(tblСтатьяРасходов_09[apr]) -> 800 | G13: =SUM(tblСтатьяРасходов_09[may]) -> 800 | H13: =SUM(tblСтатьяРасходов_09[jun]) -> 500 | I13: =SUM(tblСтатьяРасходов_09[jul]) -> 500 | J13: =SUM(tblСтатьяРасходов_09[aug]) -> 500 | K13: =SUM(tblСтатьяРасходов_09[sep]) -> 800 | L13: =SUM(tblСтатьяРасходов_09[oct]) -> 800 | M13: =SUM(tblСтатьяРасходов_09[nov]) -> 800 | N13: =SUM(tblСтатьяРасходов_09[dec]) -> 800 | O13: =SUM(tblСтатьяРасходов_09[year]) -> 8700 | P13: =SUM(tblСтатьяРасходов_09[avg]) -> 725
B14: =LOWER(Бюджет!B78) -> благотворительность | C14: =SUM(tblСтатьяРасходов_08[jan]) -> 0 | D14: =SUM(tblСтатьяРасходов_08[feb]) -> 100 | E14: =SUM(tblСтатьяРасходов_08[mar]) -> 100 | F14: =SUM(tblСтатьяРасходов_08[apr]) -> 100 | G14: =SUM(tblСтатьяРасходов_08[may]) -> 100 | H14: =SUM(tblСтатьяРасходов_08[jun]) -> 100 | I14: =SUM(tblСтатьяРасходов_08[jul]) -> 100 | J14: =SUM(tblСтатьяРасходов_08[aug]) -> 100 | K14: =SUM(tblСтатьяРасходов_08[sep]) -> 100 | L14: =SUM(tblСтатьяРасходов_08[oct]) -> 100 | M14: =SUM(tblСтатьяРасходов_08[nov]) -> 100 | N14: =SUM(tblСтатьяРасходов_08[dec]) -> 100 | O14: =SUM(tblСтатьяРасходов_08[year]) -> 1100 | P14: =SUM(tblСтатьяРасходов_08[avg]) -> 91.666667
B15: =LOWER(Бюджет!B71) -> образование | C15: =SUM(tblСтатьяРасходов_07[jan]) -> 0 | D15: =SUM(tblСтатьяРасходов_07[feb]) -> 0 | E15: =SUM(tblСтатьяРасходов_07[mar]) -> 625 | F15: =SUM(tblСтатьяРасходов_07[apr]) -> 0 | G15: =SUM(tblСтатьяРасходов_07[may]) -> 0 | H15: =SUM(tblСтатьяРасходов_07[jun]) -> 0 | I15: =SUM(tblСтатьяРасходов_07[jul]) -> 0 | J15: =SUM(tblСтатьяРасходов_07[aug]) -> 0 | K15: =SUM(tblСтатьяРасходов_07[sep]) -> 625 | L15: =SUM(tblСтатьяРасходов_07[oct]) -> 0 | M15: =SUM(tblСтатьяРасходов_07[nov]) -> 0 | N15: =SUM(tblСтатьяРасходов_07[dec]) -> 0 | O15: =SUM(tblСтатьяРасходов_07[year]) -> 1250 | P15: =SUM(tblСтатьяРасходов_07[avg]) -> 104.16667
B16: =LOWER(Бюджет!B64) -> страховка | C16: =SUM(tblСтатьяРасходов_06[jan]) -> 975 | D16: =SUM(tblСтатьяРасходов_06[feb]) -> 975 | E16: =SUM(tblСтатьяРасходов_06[mar]) -> 975 | F16: =SUM(tblСтатьяРасходов_06[apr]) -> 975 | G16: =SUM(tblСтатьяРасходов_06[may]) -> 975 | H16: =SUM(tblСтатьяРасходов_06[jun]) -> 975 | I16: =SUM(tblСтатьяРасходов_06[jul]) -> 975 | J16: =SUM(tblСтатьяРасходов_06[aug]) -> 975 | K16: =SUM(tblСтатьяРасходов_06[sep]) -> 975 | L16: =SUM(tblСтатьяРасходов_06[oct]) -> 975 | M16: =SUM(tblСтатьяРасходов_06[nov]) -> 975 | N16: =SUM(tblСтатьяРасходов_06[dec]) -> 975 | O16: =SUM(tblСтатьяРасходов_06[year]) -> 11700 | P16: =SUM(tblСтатьяРасходов_06[avg]) -> 975
B17: =LOWER(Бюджет!B57) -> здоровье | C17: =SUM(tblСтатьяРасходов_05[jan]) -> 25 | D17: =SUM(tblСтатьяРасходов_05[feb]) -> 60 | E17: =SUM(tblСтатьяРасходов_05[mar]) -> 175 | F17: =SUM(tblСтатьяРасходов_05[apr]) -> 25 | G17: =SUM(tblСтатьяРасходов_05[may]) -> 60 | H17: =SUM(tblСтатьяРасходов_05[jun]) -> 60 | I17: =SUM(tblСтатьяРасходов_05[jul]) -> 60 | J17: =SUM(tblСтатьяРасходов_05[aug]) -> 25 | K17: =SUM(tblСтатьяРасходов_05[sep]) -> 175 | L17: =SUM(tblСтатьяРасходов_05[oct]) -> 60 | M17: =SUM(tblСтатьяРасходов_05[nov]) -> 25 | N17: =SUM(tblСтатьяРасходов_05[dec]) -> 25 | O17: =SUM(tblСтатьяРасходов_05[year]) -> 775 | P17: =SUM(tblСтатьяРасходов_05[avg]) -> 64.583333
B18: =LOWER(Бюджет!B48) -> транспорт | C18: =SUM(tblСтатьяРасходов_04[jan]) -> 1110 | D18: =SUM(tblСтатьяРасходов_04[feb]) -> 1025 | E18: =SUM(tblСтатьяРасходов_04[mar]) -> 925 | F18: =SUM(tblСтатьяРасходов_04[apr]) -> 1025 | G18: =SUM(tblСтатьяРасходов_04[may]) -> 1325 | H18: =SUM(tblСтатьяРасходов_04[jun]) -> 1200 | I18: =SUM(tblСтатьяРасходов_04[jul]) -> 1100 | J18: =SUM(tblСтатьяРасходов_04[aug]) -> 1200 | K18: =SUM(tblСтатьяРасходов_04[sep]) -> 1150 | L18: =SUM(tblСтатьяРасходов_04[oct]) -> 1025 | M18: =SUM(tblСтатьяРасходов_04[nov]) -> 925 | N18: =SUM(tblСтатьяРасходов_04[dec]) -> 925 | O18: =SUM(tblСтатьяРасходов_04[year]) -> 12935 | P18: =SUM(tblСтатьяРасходов_04[avg]) -> 1077.9167
B19: =LOWER(Бюджет!B39) -> дети | C19: =SUM(tblСтатьяРасходов_03[jan]) -> 2373 | D19: =SUM(tblСтатьяРасходов_03[feb]) -> 500 | E19: =SUM(tblСтатьяРасходов_03[mar]) -> 350 | F19: =SUM(tblСтатьяРасходов_03[apr]) -> 250 | G19: =SUM(tblСтатьяРасходов_03[may]) -> 350 | H19: =SUM(tblСтатьяРасходов_03[jun]) -> 450 | I19: =SUM(tblСтатьяРасходов_03[jul]) -> 200 | J19: =SUM(tblСтатьяРасходов_03[aug]) -> 545 | K19: =SUM(tblСтатьяРасходов_03[sep]) -> 350 | L19: =SUM(tblСтатьяРасходов_03[oct]) -> 350 | M19: =SUM(tblСтатьяРасходов_03[nov]) -> 250 | N19: =SUM(tblСтатьяРасходов_03[dec]) -> 350 | O19: =SUM(tblСтатьяРасходов_03[year]) -> 6318 | P19: =SUM(tblСтатьяРасходов_03[avg]) -> 526.5
B20: =LOWER(Бюджет!B30) -> бытовые нужды | C20: =SUM(tblСтатьяРасходов_02[jan]) -> 795 | D20: =SUM(tblСтатьяРасходов_02[feb]) -> 375 | E20: =SUM(tblСтатьяРасходов_02[mar]) -> 550 | F20: =SUM(tblСтатьяРасходов_02[apr]) -> 825 | G20: =SUM(tblСтатьяРасходов_02[may]) -> 500 | H20: =SUM(tblСтатьяРасходов_02[jun]) -> 450 | I20: =SUM(tblСтатьяРасходов_02[jul]) -> 875 | J20: =SUM(tblСтатьяРасходов_02[aug]) -> 475 | K20: =SUM(tblСтатьяРасходов_02[sep]) -> 400 | L20: =SUM(tblСтатьяРасходов_02[oct]) -> 825 | M20: =SUM(tblСтатьяРасходов_02[nov]) -> 575 | N20: =SUM(tblСтатьяРасходов_02[dec]) -> 375 | O20: =SUM(tblСтатьяРасходов_02[year]) -> 7020 | P20: =SUM(tblСтатьяРасходов_02[avg]) -> 585
B21: =LOWER(Бюджет!B21) -> жилье | C21: =SUM(tblСтатьяРасходов_01[jan]) -> 1208 | D21: =SUM(tblСтатьяРасходов_01[feb]) -> 1208 | E21: =SUM(tblСтатьяРасходов_01[mar]) -> 1233 | F21: =SUM(tblСтатьяРасходов_01[apr]) -> 1208 | G21: =SUM(tblСтатьяРасходов_01[may]) -> 1158 | H21: =SUM(tblСтатьяРасходов_01[jun]) -> 1183 | I21: =SUM(tblСтатьяРасходов_01[jul]) -> 1283 | J21: =SUM(tblСтатьяРасходов_01[aug]) -> 1333 | K21: =SUM(tblСтатьяРасходов_01[sep]) -> 1208 | L21: =SUM(tblСтатьяРасходов_01[oct]) -> 1158 | M21: =SUM(tblСтатьяРасходов_01[nov]) -> 1208 | N21: =SUM(tblСтатьяРасходов_01[dec]) -> 1208 | O21: =SUM(tblСтатьяРасходов_01[year]) -> 14596 | P21: =SUM(tblСтатьяРасходов_01[avg]) -> 1216.3333
B26: Общий денежный поток | C26: =SUM(Бюджет!$C$8:C$8) -> -3714 | D26: =SUM(Бюджет!$C$8:D$8) -> 76 | E26: =SUM(Бюджет!$C$8:E$8) -> -1857 | F26: =SUM(Бюджет!$C$8:F$8) -> -3670 | G26: =SUM(Бюджет!$C$8:G$8) -> -138 | H26: =SUM(Бюджет!$C$8:H$8) -> -3731 | I26: =SUM(Бюджет!$C$8:I$8) -> -7974 | J26: =SUM(Бюджет!$C$8:J$8) -> -6827 | ... O26: =SUM(Бюджет!$C$8:O$8) -> -15538
B28: Годовой приток денежного потока | C28: =IF(Бюджет!C$8<0,NA(),IF(период+2<>COLUMN(Бюджет!C$8),NA(),Бюджет!C$8)) -> #N/A | D28: =IF(Бюджет!D$8<0,NA(),IF(период+2<>COLUMN(Бюджет!D$8),NA(),Бюджет!D$8)) -> #N/A | E28: =IF(Бюджет!E$8<0,NA(),IF(период+2<>COLUMN(Бюджет!E$8),NA(),Бюджет!E$8)) -> #N/A | F28: =IF(Бюджет!F$8<0,NA(),IF(период+2<>COLUMN(Бюджет!F$8),NA(),Бюджет!F$8)) -> #N/A | G28: =IF(Бюджет!G$8<0,NA(),IF(период+2<>COLUMN(Бюджет!G$8),NA(),Бюджет!G$8)) -> #N/A | H28: =IF(Бюджет!H$8<0,NA(),IF(период+2<>COLUMN(Бюджет!H$8),NA(),Бюджет!H$8)) -> #N/A | I28: =IF(Бюджет!I$8<0,NA(),IF(период+2<>COLUMN(Бюджет!I$8),NA(),Бюджет!I$8)) -> #N/A | J28: =IF(Бюджет!J$8<0,NA(),IF(период+2<>COLUMN(Бюджет!J$8),NA(),Бюджет!J$8)) -> #N/A | ... O28: =IF(Бюджет!O$8<0,NA(),IF(период+2<>COLUMN(Бюджет!O$8),NA(),Бюджет!O$8)) -> #N/A
B29: Годовой отток денежного потока | C29: =IF(Бюджет!C$8>=0,NA(),IF(период+2<>COLUMN(Бюджет!C$8),NA(),Бюджет!C$8)) -> #N/A | D29: =IF(Бюджет!D$8>=0,NA(),IF(период+2<>COLUMN(Бюджет!D$8),NA(),Бюджет!D$8)) -> #N/A | E29: =IF(Бюджет!E$8>=0,NA(),IF(период+2<>COLUMN(Бюджет!E$8),NA(),Бюджет!E$8)) -> -1933 | F29: =IF(Бюджет!F$8>=0,NA(),IF(период+2<>COLUMN(Бюджет!F$8),NA(),Бюджет!F$8)) -> #N/A | G29: =IF(Бюджет!G$8>=0,NA(),IF(период+2<>COLUMN(Бюджет!G$8),NA(),Бюджет!G$8)) -> #N/A | H29: =IF(Бюджет!H$8>=0,NA(),IF(период+2<>COLUMN(Бюджет!H$8),NA(),Бюджет!H$8)) -> #N/A | I29: =IF(Бюджет!I$8>=0,NA(),IF(период+2<>COLUMN(Бюджет!I$8),NA(),Бюджет!I$8)) -> #N/A | J29: =IF(Бюджет!J$8>=0,NA(),IF(период+2<>COLUMN(Бюджет!J$8),NA(),Бюджет!J$8)) -> #N/A | ... O29: =IF(Бюджет!O$8>=0,NA(),IF(период+2<>COLUMN(Бюджет!O$8),NA(),Бюджет!O$8)) -> #N/A
B37: =отображать_длительный_период -> Март
B38: =отображать_длительный_период & " Доходы" -> Март Доходы | C38: =INDEX(Бюджет!$C$6:$P$6,,период) -> 4000
B39: =отображать_длительный_период & " Расходы: " & TEXT(INDEX(Бюджет!$C$7:$P$7,,период),"# ##0р.") -> Март Расходы: 5 933р. | C39: =INDEX(Бюджет!$C$7:$P$7,,период) -> 5933
B40: =отображать_длительный_период & "Движение средств" -> МартДвижение средств | C40: =ABS(INDEX(Бюджет!$C$8:$P$8,,период)) -> 1933 | D40: =REPT("-",INDEX(Бюджет!$C$8:$P$8,,период)<0) -> -
